Workbook

Sheet 5-Year Roadmap
A1: Year | B1: Age | C1: Phase | D1: Main goal | E1: A races | F1: A-race count | G1: Run targets | H1: Bike target | I1: Status
A2: 2026 | B2: 23 | C2: Injury comeback + bike block | D2: Heal the shin; build FTP | E2: Cycling TTs (B) | F2: =COUNTIFS('Race Calendar'!$A$2:$A$73,A2,'Race Calendar'!$I$2:$I$73,"A")+COUNTIFS('Race Calendar'!$A$2:$A$73,A2,'Race Calendar'!$I$2:$I$73,"A+") -> 0 | G2: Injury: cycling only until cleared; walk–run from ~Nov if pain-free | H2: FTP test Oct; 250 W by Mar 2027
A3: 2027 | B3: 24 | C3: Engine + first duathlons | D3: First Malaysian results; SEA Games stretch | E3: TriFactor Malaysia · Asia Duathlon Cup · Sydney 10 · SEA Games (if selected) | F3: =COUNTIFS('Race Calendar'!$A$2:$A$73,A3,'Race Calendar'!$I$2:$I$73,"A")+COUNTIFS('Race Calendar'!$A$2:$A$73,A3,'Race Calendar'!$I$2:$I$73,"A+") -> 4 | G3: 5k <17:00 · 10k <35:30 · HM ~1:20 | H3: FTP 250 → 280 W
A4: 2028 | B4: 25 | C4: Podium year | D4: Powerman Malaysia podium; national top 3 | E4: NSW Duathlon · TriFactor · Asia Cups · Powerman Malaysia · KLSCM half · Zatopek | F4: =COUNTIFS('Race Calendar'!$A$2:$A$73,A4,'Race Calendar'!$I$2:$I$73,"A")+COUNTIFS('Race Calendar'!$A$2:$A$73,A4,'Race Calendar'!$I$2:$I$73,"A+") -> 6 | G4: 5k 16:00 · 10k 34:00 · HM 1:15 | H4: FTP 280–300 W
A5: 2029 | B5: 26 | C5: SEA Games | D5: Represent Malaysia at SEA Games Singapore | E5: SEA Games · TriFactor · Zofingen (if no clash) | F5: =COUNTIFS('Race Calendar'!$A$2:$A$73,A5,'Race Calendar'!$I$2:$I$73,"A")+COUNTIFS('Race Calendar'!$A$2:$A$73,A5,'Race Calendar'!$I$2:$I$73,"A+") -> 3 | G5: Hold 10k ~33:30 off the bike | H5: Race power 280+ W for 60 km
A6: 2030 | B6: 27 | C6: Long distance + first marathon | D6: Zofingen top finish; KL full marathon | E6: Powerman Malaysia · Zofingen · KLSCM full | F6: =COUNTIFS('Race Calendar'!$A$2:$A$73,A6,'Race Calendar'!$I$2:$I$73,"A")+COUNTIFS('Race Calendar'!$A$2:$A$73,A6,'Race Calendar'!$I$2:$I$73,"A+") -> 3 | G6: Marathon ~2:40 (first attempt) | H6: 4–5 h long-course power
A7: 2031 | B7: 28 | C7: Peak years | D7: SEA Games Laos medal; Zofingen podium | E7: SEA Games · TriFactor · Powerman Malaysia · Zofingen | F7: =COUNTIFS('Race Calendar'!$A$2:$A$73,A7,'Race Calendar'!$I$2:$I$73,"A")+COUNTIFS('Race Calendar'!$A$2:$A$73,A7,'Race Calendar'!$I$2:$I$73,"A+") -> 4 | G7: 10k off the bike ~33:00 | H7: Peak FTP 300+ W
A9: Notes
A10: A-race count is a formula from the Race Calendar tab; keep it to about 4–6 per year (one every 8–10 weeks).
A11: Yellow cells (Status, Result) are for you to fill in.
A12: Asian Games (Doha 2030) have no duathlon, so they're not a target. SEA Games hosts: Malaysia 2027, Singapore 2029, Laos 2031.
A13: Sydney race dates come from the club master template (2026 dates); check each year.
A14: Rule: when a Sydney race clashes with a Malaysian selection race, Malaysia comes first.

Sheet Race Calendar
A1: Year | B1: Month | C1: Date | D1: Event | E1: Type | F1: Location | G1: Country | H1: Distance | I1: Priority | J1: Why | K1: Status | L1: Result | M1: Source
A2: 2026 | B2: Oct | C2: 46310 | D2: NSW 10000m | E2: Track | F2: SOPAC | G2: AUS | H2: 10,000m | I2: Skip | J2: Injury: cycling only | K2: Planned | M2: Club master template (USYD 2026)
A3: 2026 | B3: Oct | C3: 46326 | D3: NSW 3000m | E3: Track | F3: E.S. Marks | G3: AUS | H3: 3000m | I3: Skip | J3: Injury: cycling only | K3: Planned | M3: Club master template (USYD 2026)
A4: 2026 | B4: Nov | C4: 46352 | D4: Twilight II | E4: Track | F4: SOPAC | G4: AUS | H4: 5000m | I4: Skip | J4: Injury: only if 6+ weeks pain-free running | K4: Planned | M4: Club master template (USYD 2026)
A5: 2026 | B5: Dec | C5: 46368 | D5: Treloar Shield Final | E5: Track | F5: SOPAC | G5: AUS | H5: 1500m | I5: C | J5: Only if cleared; first hit-out | K5: Planned | M5: Club master template (USYD 2026)
A6: 2026 | B6: Oct–Dec | D6: Cycling NSW time trials / club TTs | E6: Cycling TT | F6: Sydney | G6: AUS | H6: 20–40 km | I6: B | J6: Injury bike block: solo power | K6: Planned
A7: 2027 | B7: Jan | D7: NSW Duathlon State Championships | E7: Duathlon | F7: Eastern Creek, Sydney | G7: AUS | H7: 5 / 20 / 2.5 km | I7: B | J7: State title; AG Worlds qualifier | K7: Planned | M7: https://www.triathlon.org.au/events/nsw-duathlon-state-championships-3/
A8: 2027 | B8: Jun | D8: TriFactor Malaysia Duathlon | E8: Duathlon | F8: Iskandar Puteri, Johor | G8: MAS | H8: Sprint / standard | I8: A | J8: Biggest Malaysian duathlon; selectors watch | K8: Planned | M8: https://www.ticket2u.com.my/event/47517/trifactor-malaysia-duathlon-cyclerun-2026
A9: 2027 | B9: Sep | D9: Powerman Malaysia | E9: Duathlon | F9: Putrajaya | G9: MAS | H9: 10 / 60 / 10 km | I9: B | J9: Powerman Classic | K9: Planned | M9: https://powerman.org/
A10: 2027 | B10: Oct–Jun | D10: Contact Triathlon Malaysia: selection criteria + elite licence | E10: Admin | F10: — | G10: MAS | H10: — | I10: Must do | J10: Ask if duathlon is in the 2027 SEA Games | K10: Planned
A11: 2027 | B11: TBC | D11: Asia Triathlon Duathlon Cup | E11: Duathlon | F11: Asia (e.g. Tam Chuc, VIE) | G11: ASIA | H11: Sprint, elite | I11: A | J11: Continental ranking points | K11: Planned | M11: https://triathlon.org/events/2026-asia-triathlon-duathlon-cup-tam-chuc
A12: 2027 | B12: Jul | C12: 46585 | D12: World Triathlon Multisport Champs | E12: Duathlon | F12: Edmonton | G12: CAN | H12: Sprint / standard | I12: B | J12: Optional; race for Malaysia (age group) | K12: Planned | M12: https://triathlon.org/news/edmonton-to-host-the-2027-world-triathlon-multisport-championships-on-1625-july
A13: 2027 | B13: Sep | C13: 46648 | D13: SEA Games (Malaysia) — if duathlon included and selected | E13: Duathlon | F13: Malaysia | G13: MAS | H13: TBC | I13: A | J13: Home Games; stretch goal | K13: Planned | M13: https://en.wikipedia.org/wiki/2027_SEA_Games
A14: 2027 | B14: May | D14: Hoka Half | E14: Half marathon | F14: Sydney City | G14: AUS | H14: 21.1 km | I14: B | J14: Half-marathon checkpoint | K14: Planned | M14: Club master template (USYD 2026)
A15: 2027 | B15: May | D15: Sydney 10 | E15: Road 10k | F15: SOPAC | G15: AUS | H15: 10 km | I15: A | J15: 10k checkpoint | K15: Planned | M15: Club master template (USYD 2026)
A16: 2027 | B16: Jun | D16: NSW XC Champs | E16: Cross country | F16: Nowra | G16: AUS | H16: 10 km | I16: C | J16: Strength; optional | K16: Planned | M16: Club master template (USYD 2026)
A17: 2027 | B17: Jul | D17: Gold Coast Marathon weekend | E17: Half marathon | F17: Gold Coast | G17: AUS | H17: 21.1 km | I17: B | J17: Fast course | K17: Planned | M17: Club master template (USYD 2026)
A18: 2027 | B18: Jul | D18: Sydney Harbour 10 | E18: Road 10k | F18: Sydney CBD | G18: AUS | H18: 10 km | I18: B | J18: Road 10k check | K18: Planned | M18: Club master template (USYD 2026)
A19: 2027 | B19: Aug | D19: City2Surf | E19: Road | F19: CBD → Bondi | G19: AUS | H19: 14 km | I19: C | J19: Hard tempo; skip if racing in Asia | K19: Planned | M19: Club master template (USYD 2026)
A20: 2027 | B20: Oct | D20: Standard Chartered KL Marathon (KLSCM) | E20: Half marathon | F20: Kuala Lumpur | G20: MAS | H20: 21.1 km | I20: B | J20: Only if not at the SEA Games (ends 29 Sep) | K20: Planned | M20: https://www.kl-marathon.com/news/116/
A21: 2027 | B21: Oct | D21: NSW 10000m | E21: Track | F21: SOPAC | G21: AUS | H21: 10,000m | I21: B | J21: Track 10k | K21: Planned | M21: Club master template (USYD 2026)
A22: 2027 | B22: Oct | D22: NSW 3000m | E22: Track | F22: E.S. Marks | G22: AUS | H22: 3000m | I22: C | J22: Speed / relay pace | K22: Planned | M22: Club master template (USYD 2026)
A23: 2027 | B23: Nov | D23: Twilight 5000m | E23: Track | F23: SOPAC | G23: AUS | H23: 5000m | I23: B | J23: 5k checkpoint | K23: Planned | M23: Club master template (USYD 2026)
A24: 2027 | B24: Dec | D24: Zatopek:10 | E24: Track | F24: Melbourne | G24: AUS | H24: 10,000m | I24: B | J24: Fast national 10k | K24: Planned
A25: 2028 | B25: Jan | D25: NSW Duathlon State Championships | E25: Duathlon | F25: Eastern Creek, Sydney | G25: AUS | H25: 5 / 20 / 2.5 km | I25: B | J25: State title; AG Worlds qualifier | K25: Planned | M25: https://www.triathlon.org.au/events/nsw-duathlon-state-championships-3/
A26: 2028 | B26: Jun | D26: TriFactor Malaysia Duathlon | E26: Duathlon | F26: Iskandar Puteri, Johor | G26: MAS | H26: Sprint / standard | I26: A | J26: Biggest Malaysian duathlon; selectors watch | K26: Planned | M26: https://www.ticket2u.com.my/event/47517/trifactor-malaysia-duathlon-cyclerun-2026
A27: 2028 | B27: Sep | D27: Powerman Malaysia | E27: Duathlon | F27: Putrajaya | G27: MAS | H27: 10 / 60 / 10 km | I27: A | J27: Powerman Classic | K27: Planned | M27: https://powerman.org/
A28: 2028 | B28: TBC | D28: Asia Triathlon Duathlon Cups (x2) | E28: Duathlon | F28: Asia | G28: ASIA | H28: Sprint, elite | I28: A | J28: Ranking points for 2029 selection | K28: Planned
A29: 2028 | B29: TBC | D29: Malaysian national duathlon champs / trials | E29: Duathlon | F29: Malaysia | G29: MAS | H29: Standard | I29: A | J29: Main selection race for 2029 | K29: Planned
A30: 2028 | B30: Oct | D30: Powerman Würselen | E30: Duathlon | F30: Würselen | G30: GER | H30: 10 / 40 / 5 km | I30: B | J30: Optional; deep European field | K30: Planned | M30: https://powerman.org/
A31: 2028 | B31: May | D31: Hoka Half | E31: Half marathon | F31: Sydney City | G31: AUS | H31: 21.1 km | I31: B | J31: Half-marathon checkpoint | K31: Planned | M31: Club master template (USYD 2026)
A32: 2028 | B32: May | D32: Sydney 10 | E32: Road 10k | F32: SOPAC | G32: AUS | H32: 10 km | I32: A | J32: 10k checkpoint | K32: Planned | M32: Club master template (USYD 2026)
A33: 2028 | B33: Jun | D33: NSW XC Champs | E33: Cross country | F33: Nowra | G33: AUS | H33: 10 km | I33: C | J33: Strength; optional | K33: Planned | M33: Club master template (USYD 2026)
A34: 2028 | B34: Jul | D34: Gold Coast Marathon weekend | E34: Half marathon | F34: Gold Coast | G34: AUS | H34: 21.1 km | I34: B | J34: Fast course | K34: Planned | M34: Club master template (USYD 2026)
A35: 2028 | B35: Jul | D35: Sydney Harbour 10 | E35: Road 10k | F35: Sydney CBD | G35: AUS | H35: 10 km | I35: B | J35: Road 10k check | K35: Planned | M35: Club master template (USYD 2026)
A36: 2028 | B36: Aug | D36: City2Surf | E36: Road | F36: CBD → Bondi | G36: AUS | H36: 14 km | I36: C | J36: Hard tempo; skip if racing in Asia | K36: Planned | M36: Club master template (USYD 2026)
A37: 2028 | B37: Oct | D37: Standard Chartered KL Marathon (KLSCM) | E37: Half marathon | F37: Kuala Lumpur | G37: MAS | H37: 21.1 km | I37: A | J37: Top 3 Malaysian; half-marathon 1:15 goal | K37: Planned | M37: https://www.kl-marathon.com/news/116/
A38: 2028 | B38: Oct | D38: NSW 10000m | E38: Track | F38: SOPAC | G38: AUS | H38: 10,000m | I38: B | J38: Track 10k | K38: Planned | M38: Club master template (USYD 2026)
A39: 2028 | B39: Oct | D39: NSW 3000m | E39: Track | F39: E.S. Marks | G39: AUS | H39: 3000m | I39: C | J39: Speed / relay pace | K39: Planned | M39: Club master template (USYD 2026)
A40: 2028 | B40: Nov | D40: Twilight 5000m | E40: Track | F40: SOPAC | G40: AUS | H40: 5000m | I40: B | J40: 5k checkpoint | K40: Planned | M40: Club master template (USYD 2026)
...

Sheet Summary
A1: Type | B1: 2026 | C1: 2027 | D1: 2028 | E1: 2029 | F1: 2030 | G1: 2031 | H1: Total
A2: Admin | B2: =COUNTIFS('Race Calendar'!$E$2:$E$73,$A2,'Race Calendar'!$A$2:$A$73,B$1,'Race Calendar'!$I$2:$I$73,"<>Skip") -> 0 | C2: =COUNTIFS('Race Calendar'!$E$2:$E$73,$A2,'Race Calendar'!$A$2:$A$73,C$1,'Race Calendar'!$I$2:$I$73,"<>Skip") -> 1 | D2: =COUNTIFS('Race Calendar'!$E$2:$E$73,$A2,'Race Calendar'!$A$2:$A$73,D$1,'Race Calendar'!$I$2:$I$73,"<>Skip") -> 0 | E2: =COUNTIFS('Race Calendar'!$E$2:$E$73,$A2,'Race Calendar'!$A$2:$A$73,E$1,'Race Calendar'!$I$2:$I$73,"<>Skip") -> 0 | F2: =COUNTIFS('Race Calendar'!$E$2:$E$73,$A2,'Race Calendar'!$A$2:$A$73,F$1,'Race Calendar'!$I$2:$I$73,"<>Skip") -> 0 | G2: =COUNTIFS('Race Calendar'!$E$2:$E$73,$A2,'Race Calendar'!$A$2:$A$73,G$1,'Race Calendar'!$I$2:$I$73,"<>Skip") -> 0 | H2: =SUM(B2:G2) -> 1
A3: Cross country | B3: =COUNTIFS('Race Calendar'!$E$2:$E$73,$A3,'Race Calendar'!$A$2:$A$73,B$1,'Race Calendar'!$I$2:$I$73,"<>Skip") -> 0 | C3: =COUNTIFS('Race Calendar'!$E$2:$E$73,$A3,'Race Calendar'!$A$2:$A$73,C$1,'Race Calendar'!$I$2:$I$73,"<>Skip") -> 1 | D3: =COUNTIFS('Race Calendar'!$E$2:$E$73,$A3,'Race Calendar'!$A$2:$A$73,D$1,'Race Calendar'!$I$2:$I$73,"<>Skip") -> 1 | E3: =COUNTIFS('Race Calendar'!$E$2:$E$73,$A3,'Race Calendar'!$A$2:$A$73,E$1,'Race Calendar'!$I$2:$I$73,"<>Skip") -> 1 | F3: =COUNTIFS('Race Calendar'!$E$2:$E$73,$A3,'Race Calendar'!$A$2:$A$73,F$1,'Race Calendar'!$I$2:$I$73,"<>Skip") -> 0 | G3: =COUNTIFS('Race Calendar'!$E$2:$E$73,$A3,'Race Calendar'!$A$2:$A$73,G$1,'Race Calendar'!$I$2:$I$73,"<>Skip") -> 1 | H3: =SUM(B3:G3) -> 4
A4: Cycling TT | B4: =COUNTIFS('Race Calendar'!$E$2:$E$73,$A4,'Race Calendar'!$A$2:$A$73,B$1,'Race Calendar'!$I$2:$I$73,"<>Skip") -> 1 | C4: =COUNTIFS('Race Calendar'!$E$2:$E$73,$A4,'Race Calendar'!$A$2:$A$73,C$1,'Race Calendar'!$I$2:$I$73,"<>Skip") -> 0 | D4: =COUNTIFS('Race Calendar'!$E$2:$E$73,$A4,'Race Calendar'!$A$2:$A$73,D$1,'Race Calendar'!$I$2:$I$73,"<>Skip") -> 0 | E4: =COUNTIFS('Race Calendar'!$E$2:$E$73,$A4,'Race Calendar'!$A$2:$A$73,E$1,'Race Calendar'!$I$2:$I$73,"<>Skip") -> 0 | F4: =COUNTIFS('Race Calendar'!$E$2:$E$73,$A4,'Race Calendar'!$A$2:$A$73,F$1,'Race Calendar'!$I$2:$I$73,"<>Skip") -> 0 | G4: =COUNTIFS('Race Calendar'!$E$2:$E$73,$A4,'Race Calendar'!$A$2:$A$73,G$1,'Race Calendar'!$I$2:$I$73,"<>Skip") -> 0 | H4: =SUM(B4:G4) -> 1
A5: Duathlon | B5: =COUNTIFS('Race Calendar'!$E$2:$E$73,$A5,'Race Calendar'!$A$2:$A$73,B$1,'Race Calendar'!$I$2:$I$73,"<>Skip") -> 0 | C5: =COUNTIFS('Race Calendar'!$E$2:$E$73,$A5,'Race Calendar'!$A$2:$A$73,C$1,'Race Calendar'!$I$2:$I$73,"<>Skip") -> 6 | D5: =COUNTIFS('Race Calendar'!$E$2:$E$73,$A5,'Race Calendar'!$A$2:$A$73,D$1,'Race Calendar'!$I$2:$I$73,"<>Skip") -> 6 | E5: =COUNTIFS('Race Calendar'!$E$2:$E$73,$A5,'Race Calendar'!$A$2:$A$73,E$1,'Race Calendar'!$I$2:$I$73,"<>Skip") -> 5 | F5: =COUNTIFS('Race Calendar'!$E$2:$E$73,$A5,'Race Calendar'!$A$2:$A$73,F$1,'Race Calendar'!$I$2:$I$73,"<>Skip") -> 4 | G5: =COUNTIFS('Race Calendar'!$E$2:$E$73,$A5,'Race Calendar'!$A$2:$A$73,G$1,'Race Calendar'!$I$2:$I$73,"<>Skip") -> 5 | H5: =SUM(B5:G5) -> 26
A6: Half marathon | B6: =COUNTIFS('Race Calendar'!$E$2:$E$73,$A6,'Race Calendar'!$A$2:$A$73,B$1,'Race Calendar'!$I$2:$I$73,"<>Skip") -> 0 | C6: =COUNTIFS('Race Calendar'!$E$2:$E$73,$A6,'Race Calendar'!$A$2:$A$73,C$1,'Race Calendar'!$I$2:$I$73,"<>Skip") -> 3 | D6: =COUNTIFS('Race Calendar'!$E$2:$E$73,$A6,'Race Calendar'!$A$2:$A$73,D$1,'Race Calendar'!$I$2:$I$73,"<>Skip") -> 3 | E6: =COUNTIFS('Race Calendar'!$E$2:$E$73,$A6,'Race Calendar'!$A$2:$A$73,E$1,'Race Calendar'!$I$2:$I$73,"<>Skip") -> 3 | F6: =COUNTIFS('Race Calendar'!$E$2:$E$73,$A6,'Race Calendar'!$A$2:$A$73,F$1,'Race Calendar'!$I$2:$I$73,"<>Skip") -> 1 | G6: =COUNTIFS('Race Calendar'!$E$2:$E$73,$A6,'Race Calendar'!$A$2:$A$73,G$1,'Race Calendar'!$I$2:$I$73,"<>Skip") -> 2 | H6: =SUM(B6:G6) -> 12
A7: Marathon | B7: =COUNTIFS('Race Calendar'!$E$2:$E$73,$A7,'Race Calendar'!$A$2:$A$73,B$1,'Race Calendar'!$I$2:$I$73,"<>Skip") -> 0 | C7: =COUNTIFS('Race Calendar'!$E$2:$E$73,$A7,'Race Calendar'!$A$2:$A$73,C$1,'Race Calendar'!$I$2:$I$73,"<>Skip") -> 0 | D7: =COUNTIFS('Race Calendar'!$E$2:$E$73,$A7,'Race Calendar'!$A$2:$A$73,D$1,'Race Calendar'!$I$2:$I$73,"<>Skip") -> 0 | E7: =COUNTIFS('Race Calendar'!$E$2:$E$73,$A7,'Race Calendar'!$A$2:$A$73,E$1,'Race Calendar'!$I$2:$I$73,"<>Skip") -> 0 | F7: =COUNTIFS('Race Calendar'!$E$2:$E$73,$A7,'Race Calendar'!$A$2:$A$73,F$1,'Race Calendar'!$I$2:$I$73,"<>Skip") -> 1 | G7: =COUNTIFS('Race Calendar'!$E$2:$E$73,$A7,'Race Calendar'!$A$2:$A$73,G$1,'Race Calendar'!$I$2:$I$73,"<>Skip") -> 1 | H7: =SUM(B7:G7) -> 2
A8: Multi-sport Games | B8: =COUNTIFS('Race Calendar'!$E$2:$E$73,$A8,'Race Calendar'!$A$2:$A$73,B$1,'Race Calendar'!$I$2:$I$73,"<>Skip") -> 0 | C8: =COUNTIFS('Race Calendar'!$E$2:$E$73,$A8,'Race Calendar'!$A$2:$A$73,C$1,'Race Calendar'!$I$2:$I$73,"<>Skip") -> 0 | D8: =COUNTIFS('Race Calendar'!$E$2:$E$73,$A8,'Race Calendar'!$A$2:$A$73,D$1,'Race Calendar'!$I$2:$I$73,"<>Skip") -> 0 | E8: =COUNTIFS('Race Calendar'!$E$2:$E$73,$A8,'Race Calendar'!$A$2:$A$73,E$1,'Race Calendar'!$I$2:$I$73,"<>Skip") -> 0 | F8: =COUNTIFS('Race Calendar'!$E$2:$E$73,$A8,'Race Calendar'!$A$2:$A$73,F$1,'Race Calendar'!$I$2:$I$73,"<>Skip") -> 0 | G8: =COUNTIFS('Race Calendar'!$E$2:$E$73,$A8,'Race Calendar'!$A$2:$A$73,G$1,'Race Calendar'!$I$2:$I$73,"<>Skip") -> 0 | H8: =SUM(B8:G8) -> 0
A9: Road | B9: =COUNTIFS('Race Calendar'!$E$2:$E$73,$A9,'Race Calendar'!$A$2:$A$73,B$1,'Race Calendar'!$I$2:$I$73,"<>Skip") -> 0 | C9: =COUNTIFS('Race Calendar'!$E$2:$E$73,$A9,'Race Calendar'!$A$2:$A$73,C$1,'Race Calendar'!$I$2:$I$73,"<>Skip") -> 1 | D9: =COUNTIFS('Race Calendar'!$E$2:$E$73,$A9,'Race Calendar'!$A$2:$A$73,D$1,'Race Calendar'!$I$2:$I$73,"<>Skip") -> 1 | E9: =COUNTIFS('Race Calendar'!$E$2:$E$73,$A9,'Race Calendar'!$A$2:$A$73,E$1,'Race Calendar'!$I$2:$I$73,"<>Skip") -> 1 | F9: =COUNTIFS('Race Calendar'!$E$2:$E$73,$A9,'Race Calendar'!$A$2:$A$73,F$1,'Race Calendar'!$I$2:$I$73,"<>Skip") -> 0 | G9: =COUNTIFS('Race Calendar'!$E$2:$E$73,$A9,'Race Calendar'!$A$2:$A$73,G$1,'Race Calendar'!$I$2:$I$73,"<>Skip") -> 1 | H9: =SUM(B9:G9) -> 4
A10: Road 10k | B10: =COUNTIFS('Race Calendar'!$E$2:$E$73,$A10,'Race Calendar'!$A$2:$A$73,B$1,'Race Calendar'!$I$2:$I$73,"<>Skip") -> 0 | C10: =COUNTIFS('Race Calendar'!$E$2:$E$73,$A10,'Race Calendar'!$A$2:$A$73,C$1,'Race Calendar'!$I$2:$I$73,"<>Skip") -> 2 | D10: =COUNTIFS('Race Calendar'!$E$2:$E$73,$A10,'Race Calendar'!$A$2:$A$73,D$1,'Race Calendar'!$I$2:$I$73,"<>Skip") -> 2 | E10: =COUNTIFS('Race Calendar'!$E$2:$E$73,$A10,'Race Calendar'!$A$2:$A$73,E$1,'Race Calendar'!$I$2:$I$73,"<>Skip") -> 2 | F10: =COUNTIFS('Race Calendar'!$E$2:$E$73,$A10,'Race Calendar'!$A$2:$A$73,F$1,'Race Calendar'!$I$2:$I$73,"<>Skip") -> 0 | G10: =COUNTIFS('Race Calendar'!$E$2:$E$73,$A10,'Race Calendar'!$A$2:$A$73,G$1,'Race Calendar'!$I$2:$I$73,"<>Skip") -> 2 | H10: =SUM(B10:G10) -> 8
A11: Track | B11: =COUNTIFS('Race Calendar'!$E$2:$E$73,$A11,'Race Calendar'!$A$2:$A$73,B$1,'Race Calendar'!$I$2:$I$73,"<>Skip") -> 1 | C11: =COUNTIFS('Race Calendar'!$E$2:$E$73,$A11,'Race Calendar'!$A$2:$A$73,C$1,'Race Calendar'!$I$2:$I$73,"<>Skip") -> 4 | D11: =COUNTIFS('Race Calendar'!$E$2:$E$73,$A11,'Race Calendar'!$A$2:$A$73,D$1,'Race Calendar'!$I$2:$I$73,"<>Skip") -> 4 | E11: =COUNTIFS('Race Calendar'!$E$2:$E$73,$A11,'Race Calendar'!$A$2:$A$73,E$1,'Race Calendar'!$I$2:$I$73,"<>Skip") -> 0 | F11: =COUNTIFS('Race Calendar'!$E$2:$E$73,$A11,'Race Calendar'!$A$2:$A$73,F$1,'Race Calendar'!$I$2:$I$73,"<>Skip") -> 0 | G11: =COUNTIFS('Race Calendar'!$E$2:$E$73,$A11,'Race Calendar'!$A$2:$A$73,G$1,'Race Calendar'!$I$2:$I$73,"<>Skip") -> 0 | H11: =SUM(B11:G11) -> 9
A12: Total | B12: =SUM(B2:B11) -> 2 | C12: =SUM(C2:C11) -> 18 | D12: =SUM(D2:D11) -> 17 | E12: =SUM(E2:E11) -> 12 | F12: =SUM(F2:F11) -> 6 | G12: =SUM(G2:G11) -> 12 | H12: =SUM(H2:H11) -> 67
A14: Counts races not marked Skip, by type and year.
